Workbook
Name a: Resultat!$1:$7
Name agios_four_N: Resultat!$H$95
Name Assurances: Resultat!$H$51
Name aut_achat_N: Resultat!$H$46
Name aut_ch_except_N: Resultat!$H$118
Name aut_ch_expl_N: Resultat!$H$71
Name aut_ch_externe_N: Resultat!$H$57
Name aut_ch_fi_N: Resultat!$H$97
Name aut_prod_except_N: Resultat!$H$112
Name aut_prod_fi_N: Resultat!$H$86
Name aut_tx_N: Resultat!$H$18
Name Bilan: [1]actif!$F$46
Name CA_N: Resultat!$H$24
Name carburant_N: Resultat!$H$41
Name ChargSoc_N: Resultat!$F$62
Name credit_debit: [2]compta_n!$E$1:$E$65536
Name debit_credit: [2]compta_n!$D$1:$D$65536
Name doc: Resultat!$H$52
Name dot_amort_except_N: Resultat!$H$117
Name dot_amort_fi_N: Resultat!$H$98
Name e: Resultat!$1:$7
Name ent_rep_N: Resultat!$H$50
Name Excel_BuiltIn_Print_Area_5: Resultat!$A$1:$K$129
Name Excel_BuiltIn_Print_Titles_5: Resultat!$1:$7
Name honoraires_N: Resultat!$H$54
Name indemn_adm_N: Resultat!$H$70
Name interet_banque_N: Resultat!$H$96
Name location_N: Resultat!$H$49
Name lub_piece_N: Resultat!$H$39
Name M_actif_circ: Actif!$H$49
Name M_Actif_immo: Actif!$H$33
Name M_aut_immo: Actif!$H$31
Name M_aut_immo_corp: Actif!$H$23
Name M_aut_immo_incorp: Actif!$H$15
Name M_avance: Actif!$H$42
Name M_charge_differe: Actif!#REF!
Name M_construc: Actif!$H$21
Name M_creance_adh: Actif!$H$43
Name M_creance_adh_cs: Actif!$H$44
Name M_frais_etab: Actif!$H$14
Name M_immo_en_cour: Actif!$H$24
Name M_inst_tech: Actif!$H$22
Name M_marchand: Actif!$H$38
Name M_mat_conso: Actif!$H$36
Name M_participation: Actif!$H$27
Name M_pers: Actif!$H$45
Name M_terrain: Actif!$H$20
Name mat_incorpo_N: Resultat!$H$42
Name N_actif_circ_amo: Actif!$E$49
Name N_actif_circ_brut: Actif!$D$49
Name N_Actif_immo_amo: Actif!$E$33
Name N_Actif_immo_brut: Actif!$D$33
Name N_Actif_tot_amo: Actif!$E$52
Name N_Actif_tot_brut: Actif!$D$52
Name N_aut_immo_amo: Actif!$E$31
Name N_aut_immo_brut: Actif!$D$31
Name N_aut_immo_corp_amo: Actif!$E$23
Name N_aut_immo_corp_brut: Actif!$D$23
Name N_aut_immo_corp_net: Actif!$F$23
Name N_aut_immo_incorp: Actif!$D$15

Sheet Temp
B1: Nom de la Cuma | C1: TEST
B2: Numéro d'agrément | C2: 999D0001
B3: Numéro de gestion | C3: 999001
B4: Code postal | C4: 75011
B5: Ville | C5: PARIS
B6: Adresse | C6: Rue Sedaine
B7: Siren | C7: 99988877700021
B8: Cloture N
B9: Cloture N-1 | C9: clot
B10: Cloture N-2 | C10: clot
B11: ETB
A12: datedebut | C12: 01/01/2025 | D12: 01/01/2024 | E12: 01/01/2023
A13: datefin | C13: 31/12/2025 | D13: 31/12/2024 | E13: 31/12/2023
A14: critere | C14: SO | D14: SO
A15: Compte=(704-706;7094-7096) credit=positif | B15: Activité de services | C15: 553345.57 | D15: 473301.03 | E15: 497531.42
A16: compte=(70612;709612) | B16: Dont Travaux de culture | C16: 122703.56 | D16: 100350.24 | E16: 124658.76
A17: compte=(70613;709613) | B17: Dont Travaux de récolte | C17: 244876.81 | D17: 227035.41 | E17: 227631.48
A18: compte=(7063;70963) | B18: Dont Travaux inter CUMA | C18: 0 | D18: 0 | E18: 0
A19: compte=(7062;70962) | B19: Dont Travaux tiers non associés | C19: 0 | D19: 0 | E19: 0
A20: Compte=(70614-70618;7094;70611) | B20: Dont Autres travaux | C20: 185765.2 | D20: 145915.38 | E20: 145241.18
A21: Compte=(703;708;7090;7093;7098) | B21: Produits des activités annexes | C21: 8963.38 | D21: 27354 | E21: 20038.7
A22: compte=(7084) | B22: Mise à disposition du personnel | C22: 0 | D22: 5351 | E22: 1674
A23: Compte=(713) | B23: Activité de services | C23: 0 | D23: 0 | E23: 0
A24: compte=(72) | B24: Production immobilisée | C24: 0 | D24: 0 | E24: 0
A25: compte=(74) | B25: Subventions d'exploitation | C25: 8433.84 | D25: 790.39 | E25: 0
A26: compte=(747) | B26: Dont Quote-part des subventions d'investissement virées au résultat de l'exercice | C26: 0 | D26: 790.39 | E26: 0
... A92: Compte=(70;74-746;748-749;60;61;62;63;64) credit = positif | B92: Excédent brut d'exploitation | C92: 235445.07 | D92: 223675.74 | E92: 261796.64
A93: datedebut | C93: 01/01/2000 | D93: 01/01/2000 | E93: 01/01/2000
A94: compte=(109) credit=negatif | B94: Capital souscrit non appelé | C94: 0 | D94: 0 | E94: 0
A95: compte=(201) credit=negatif | B95: Frais d'établissement (brut) | C95: 0 | D95: 0 | E95: 0
A96: compte=(2801;2901) credit=positif | B96: Frais d'établissement (amort) | C96: 0 | D96: 0 | E96: 0
A97: compte=(203) credit=negatif | B97: Frais de recherche et de développement (brut) | C97: 0 | D97: 0 | E97: 0
A98: compte=(2803;2903) credit=positif | B98: Frais de recherche et de développement (amort) | C98: 0 | D98: 0 | E98: 0
A99: compte=(205) credit=negatif | B99: Concessions,brevets,licences, marques, procédés, logiciels, droits et valeurs similaires(brut) | C99: 0 | D99: 0 | E99: 0
A100: compte=(2805;2905) credit=positif | B100: Concessions,brevets,licences, marques, procédés, logiciels, droits et valeurs similaires (amort) | C100: 0 | D100: 0 | E100: 0
A101: compte=(200;202;204;206-209) credit=negatif | B101: Autres immobilisations incorporelles (brut) | C101: 0 | D101: 0 | E101: 0
A102: compte=(2800;2802;2804;2806-2809;2900;2902;2904;2906-2909) credit=positif | B102: Autres immobilisations incorporelles (amort) | C102: 0 | D102: 0 | E102: 0
A103: compte=(237) credit=negatif | B103: Avances et acomptes sur immobilisations incorporelles (brut) | C103: 0 | D103: 0 | E103: 0
A104: compte=(2937) credit=positif | B104: Avances et acomptes sur immobilisations incorporelles (amort) | C104: 0 | D104: 0 | E104: 0
A105: compte=(211;212) credit=negatif | B105: Terrains (brut) | C105: 5180 | D105: 5180 | E105: 5180
...

Sheet Actif
B2: =Temp!C1 -> TEST | F2: ="Exercice "&RIGHT(Temp!C13,4) -> Exercice 2025
C3: ="Dossier "&Temp!C3 -> Dossier 999001 | F3: du | H3: =Temp!C12 -> 01/01/2025
C4: ="Numéro d'agrément : "&Temp!C2 -> Numéro d'agrément : 999D0001 | F4: au | H4: =Temp!C13 -> 31/12/2025
B5: BILAN
B6: ACTIF
A10: ACTIF | D10: BRUT | E10: AMORT | F10: NET N | H10: NET N-1
A11: 109 | C11: Capital souscrit non appelé | D11: =Temp!C94 -> 0 | F11: =D11 -> 0 | H11: =Temp!D94 -> 0
A12: ACTIF IMMOBILISE
B13: IMMOBILISAT. INCORPO.
A14: 201 | C14: Frais d'établissement | D14: =Temp!C95 -> 0 | E14: =Temp!C96 -> 0 | F14: =N_Frais_etab_brut-N_Frais_etab_amo -> 0 | H14: =Temp!D95-Temp!D96 -> 0
A15: 203 | C15: Frais de recherche et développement | D15: =Temp!C97 -> 0 | E15: =Temp!C98 -> 0 | F15: =N_aut_immo_incorp-N_aut_immo_incorp_amo -> 0 | H15: =Temp!D97-Temp!D98 -> 0
A16: 205 | C16: Concessions, brevets, licences, marques, procédés, logiciels, droits et valeurs similaires | D16: =Temp!C99 -> 0 | E16: =Temp!C100 -> 0 | F16: =D16-E16 -> 0 | H16: =Temp!D99-Temp!D100 -> 0
A17: 20 | C17: Autres immobilisations incorporelles | D17: =Temp!C101 -> 0 | E17: =Temp!C102 -> 0 | F17: =D17-E17 -> 0 | H17: =Temp!D101-Temp!D102 -> 0
A18: 237 | C18: Avances et acomptes sur immobilisations incorporelles | D18: =Temp!C103 -> 0 | E18: =Temp!C104 -> 0 | F18: =D18-E18 -> 0 | H18: =Temp!D103-Temp!D104 -> 0
B19: IMMOBILISAT. CORPO.
A20: 211+212 | C20: Terrains | D20: =Temp!C105 -> 5180 | E20: =Temp!C106 -> 0 | F20: =N_terrain_brut-N_terrain_amo -> 5180 | H20: =Temp!D105-Temp!D106 -> 5180
A21: 213+214 | C21: Constructions | D21: =Temp!C107 -> 41759.49 | E21: =Temp!C108 -> 34670.69 | F21: =N_construc_brut-N_construc_amo -> 7088.8 | H21: =Temp!D107-Temp!D108 -> 7088.8
A22: 215 | C22: Install. techniques, matériels et outillage | D22: =Temp!C109 -> 3057835.5 | E22: =Temp!C110 -> 927922.27 | F22: =N_inst_tech_brut-N_inst_tech_amo -> 2129913.2 | H22: =Temp!D109-Temp!D110 -> 1555255.3
A23: 21+22 | C23: Autres immobilisations corporelles | D23: =Temp!C111 -> 0 | E23: =Temp!C112 -> 0 | F23: =N_aut_immo_corp_brut-N_aut_immo_corp_amo -> 0 | H23: =Temp!D111-Temp!D112 -> 0
A24: 23 | C24: Immobilisations corporelles en cours | D24: =Temp!C113 -> 0 | F24: =N_immo_en_cour_brut-N_immo_en_cour_amo -> 0 | H24: =Temp!D113 -> 0
A25: 238 | C25: Avances et acomptes sur immobilisations corporelles | D25: =Temp!C114 -> 26250 | E25: =Temp!C115 -> 0 | F25: =D25-E25 -> 26250 | H25: =Temp!D114-Temp!D115 -> 0
B26: IMMOBILISAT. FINANCIERES
A27: 262 | C27: Participations à des org. Coop. agricoles | D27: =Temp!C116 -> 947.92 | E27: =Temp!C117 -> 0 | F27: =N_participation_brut-N_participation_amo -> 947.92 | H27: =Temp!D116-Temp!D117 -> 947.92
A28: 26 | C28: Autres participations | D28: =Temp!C118 -> 0 | E28: =Temp!C119 -> 0 | F28: =D28-E28 -> 0 | H28: =Temp!D118-Temp!D119 -> 0
A29: 267+268 | C29: Créances rattachées à des participations | D29: =Temp!C120 -> 0 | E29: =Temp!C121 -> 0 | F29: =D29-E29 -> 0 | H29: =Temp!D120-Temp!D121 -> 0
A30: 271+272 | C30: Autres titres immobilisés, PS banques... | D30: =Temp!C122 -> 2249.1 | E30: =Temp!C123 -> 0 | F30: =D30-E30 -> 2249.1 | H30: =Temp!D122-Temp!D123 -> 2180.25
A31: 274 | C31: Prêts | D31: =Temp!C124 -> 0 | E31: =Temp!C125 -> 0 | F31: =N_aut_immo_brut-N_aut_immo_amo -> 0 | H31: =Temp!D124-Temp!D125 -> 0
A32: 27 | C32: Autres immobilisations financières | D32: =Temp!C126 -> 0 | E32: =Temp!C127 -> 0 | F32: =N_reste_immo_brut-N_reste_immo_amo -> 0 | H32: =Temp!D126-Temp!D127 -> 0
C33: TOTAL ACTIF IMMOBILISE | D33: =SUM(D27:D32,D20:D25,D14:D18) -> 3134222 | E33: =SUM(E27:E32,E20:E25,E14:E18) -> 962592.96 | F33: =N_Actif_immo_brut-N_Actif_immo_amo -> 2171629.1 | H33: =SUM(H27:H32,H20:H25,H14:H18) -> 1570652.3
A34: ACTIF CIRCULANT
B35: STOCKS ET EN-COURS
A36: 32 | C36: Matières consommables et emballage | D36: =Temp!C128 -> 2274.34 | E36: =Temp!C129 -> 0 | F36: =N_mat_conso_brut-N_mat_conso_amo -> 2274.34 | H36: =Temp!D128-Temp!D129 -> 2274.34
A37: 34 | C37: En cours de production de services | D37: =Temp!C130 -> 0 | E37: =Temp!C131 -> 0 | F37: =N_encours_Prod_brut-N_aut_stock_amo -> 0 | H37: =Temp!D130-Temp!D131 -> 0
C38: Marchandises
A39: 375 | C39: Activité d'approvisionnement | D39: =Temp!C132 -> 0 | E39: =Temp!C133 -> 0 | F39: =D39-E39 -> 0 | H39: =Temp!D132-Temp!D133 -> 0
A40: 4091 | C40: Avances et acomptes versés sur commandes et apports | D40: =Temp!C134 -> 0 | F40: =D40 -> 0 | H40: =Temp!D134 -> 0
B41: CREANCES
A42: 45 | C42: Créances associés coopérateurs et comptes rattachés (1) | D42: =Temp!C136 -> 103761.18 | E42: =Temp!C138 -> 8506.71 | F42: =Temp!C136-Temp!C138 -> 95254.47 | H42: =Temp!D136-Temp!D138 -> 112235.51
A43: 41 | C43: Clients et comptes rattachés | D43: =Temp!C140 -> 4981.17 | E43: =Temp!C142 -> 0 | F43: =Temp!C140-Temp!C142 -> 4981.17 | H43: =Temp!D140-Temp!D142 -> 5014.38
A44: 40-49 | C44: Autres créances | D44: =Temp!C144 -> 68114.86 | E44: =Temp!C146 -> 0 | F44: =Temp!C144-Temp!C146 -> 68114.86 | H44: =Temp!D144-Temp!D146 -> 10756.21
...

Sheet Passif
B2: =Temp!C1 -> TEST | F2: ="Exercice "&RIGHT(Temp!C13,4) -> Exercice 2025
C3: ="Dossier "&Temp!C3 -> Dossier 999001 | F3: du | H3: =Temp!C12 -> 01/01/2025
C4: ="Numéro d'agrément : "&Temp!C2 -> Numéro d'agrément : 999D0001 | F4: au | H4: =Temp!C13 -> 31/12/2025
B5: BILAN
B6: PASSIF
A10: PASSIF | F10: NET N | H10: NET N-1
A11: CAPITAUX PROPRES
A12: 101 | C12: Capital social | D12: dont versé : | E12: =Temp!C163 -> 150572 | F12: =Temp!C162 -> 150862 | H12: =Temp!D162 -> 150862
A13: 104 | C13: Droits d'entrée | F13: =Temp!C164 -> 0 | H13: =Temp!D164 -> 0
A14: 105 | C14: Écarts de réévaluation | F14: =Temp!C165 -> 0 | H14: =Temp!D165 -> 0
C15: Réserves
A16: 1061 | C16: Réserves légale | F16: =Temp!C166 -> 59116.92 | H16: =Temp!D166 -> 59116.92
C17: Réserves indisponibles
A18: 10621 | C18: - provenant des subventions reçues de l'état, des collectivité publiques et des établissements publics | F18: =Temp!C167 -> 65079.25 | H18: =Temp!D167 -> 65079.25
A19: 10622 | C19: - provenant des opérations TNA | F19: =Temp!C168 -> 0 | H19: =Temp!D168 -> 0
A20: 10623 | C20: - provenant des dévolutions | F20: =Temp!C169 -> 22991.67 | H20: =Temp!D169 -> 22991.67
A21: 10624 à 10649 | C21: - autres | F21: =Temp!C170 -> 0 | H21: =Temp!D170 -> 0
A22: 1063 | C22: Réserves statutaires ou contractuelles | F22: =Temp!C171 -> 0 | H22: =Temp!D171 -> 0
A23: 1064 | C23: Réserves réglementées | F23: =Temp!C172 -> 0 | H23: =Temp!D172 -> 0
A24: 1068 | C24: Autres réserves | F24: =Temp!C173 -> 417702.82 | H24: =Temp!D173 -> 417702.82
A25: 1106 | C25: Report pour parfaire l'intérêt servi aux parts sociales | F25: =Temp!C174 -> 0 | H25: =Temp!D174 -> 0
A26: 1107 | C26: Report à nouveau pour ristournes éventuelles | F26: =Temp!C175 -> 0 | H26: =Temp!D175 -> 0
A27: 11 sauf 1106 & 1107 | C27: Report à nouveau débiteur | F27: =Temp!C177 -> 0 | H27: =Temp!D177 -> 0
A28: 1-5 | C28: Résultat de l'exercice (excédent ou déficit) | F28: =Temp!C178 -> 362759.63 | H28: =Temp!D178 -> 10029.72
A29: 13 | C29: Subventions d'investissement | F29: =Temp!C179 -> 3429.11 | H29: =Temp!D179 -> 3429.11
A30: 131 | C30: Part de la subvention d'investissement affectable au compte de resultat | E30: =Temp!C180 -> 4219.5
A31: 139 | C31: Montant de la subvention d'investissement inscrite au compte de resultat | E31: =Temp!C181 -> -790.39
A32: 14 | C32: Provisions réglementées | F32: =Temp!C182 -> 0 | H32: =Temp!D182 -> 0
A33: TOTAL DES CAPITAUX PROPRES | F33: =SUM(F12:F32) -> 1081941.4 | H33: =SUM(H12:H32) -> 729211.49
A34: AUTRES FONDS PROPRES
A35: 1671 | C35: Produits des émissions de titres participatifs | F35: =Temp!C183 -> 0 | H35: =Temp!D183 -> 0
A36: 1674 | C36: Avances conditionnées | F36: =Temp!C184 -> 0 | H36: =Temp!D184 -> 0
A37: TOTAL DES AUTRES FONDS PROPRES | F37: =SUM(F35:F36) -> 0 | H37: =SUM(H35:H36) -> 0
A38: PROVISIONS POUR RISQUES ET CHARGES
A39: 151 | C39: Provisions pour risques | F39: =Temp!C185 -> 0 | H39: =Temp!D185 -> 0
A40: 15 | C40: Provisions pour charges | F40: =Temp!C186 -> 0 | H40: =Temp!D186 -> 0
A41: TOTAL DES PROVISIONS | F41: =SUM(F39:F40) -> 0 | H41: =SUM(H39:H40) -> 0
A42: DETTES
A43: 162 | C43: Emprunts et dettes coopératifs | F43: =Temp!C187 -> 0 | H43: =Temp!D187 -> 0
A44: 164+51 | C44: Emprunts et dettes auprès des établissements de crédit | F44: =Temp!C188+Temp!C190 -> 1484732.6 | H44: =Temp!D188+Temp!D190 -> 1161997.9
...

Sheet Resultat
B2: =Temp!C1 -> TEST | H2: ="Exercice "&RIGHT(Temp!C13,4) -> Exercice 2025
B3: ="Dossier "&Temp!C3 -> Dossier 999001 | H3: du | J3: =Temp!C12 -> 01/01/2025
B4: ="Numéro d'agrément : "&Temp!C2 -> Numéro d'agrément : 999D0001 | H4: au | J4: =Temp!C13 -> 31/12/2025
A6: COMPTE DE RESULTAT
A9: RESULTAT D'EXPLOITATION (Hors Taxes) | H9: TOTAL N | J9: ANNEE N-1 | K9: Var.n/n-1
A10: PRODUITS D'EXPLOITATION
B12: Production vendue et cédée
A13: 704-706 | C13: Activité de services | H13: =Temp!C15 -> 553345.57 | J13: =Temp!D15 -> 473301.03 | K13: =IF(J13>0,(H13-J13)/J13," ") -> 0.16911972
A14: 70612 | C14: Travaux de culture | G14: =Temp!C16 -> 122703.56 | J14: =Temp!D16 -> 100350.24 | K14: =IF(J14>0,(G14-J14)/J14," ") -> 0.22275303
A15: 70613 | C15: Travaux de récolte | G15: =Temp!C17 -> 244876.81 | J15: =Temp!D17 -> 227035.41 | K15: =IF(G15>0,(G15-J15)/J15," ") -> 0.078584217
A16: 7063 | C16: Travaux inter CUMA | G16: =Temp!C18 -> 0 | J16: =Temp!D18 -> 0 | K16: =IF(J16>0,(G16-J16)/J16," ")
A17: 7062 | C17: Travaux pour tiers non associés | G17: =Temp!C19 -> 0 | J17: =Temp!D19 -> 0 | K17: =IF(J17>0,(G17-J17)/J17," ")
A18: 70614-70618 | C18: Autres travaux | G18: =Temp!C20 -> 185765.2 | J18: =Temp!D20 -> 145915.38 | K18: =IF(J18>0,(G18-J18)/J18," ") -> 0.27310226
A19: 703+708 | B19: Produits d'activités annexes | H19: =Temp!C21 -> 8963.38 | J19: =Temp!D21 -> 27354 | K19: =IF(J19>0,(H19-J19)/J19," ") -> -0.67231922
A20: 7084 | C20: Mise à disposition de personnel | G20: =Temp!C22 -> 0 | J20: =Temp!D22 -> 5351 | K20: =IF(J20>0,(G20-J20)/J20," ") -> -1
C21: Autres | G21: =H19-G20 -> 8963.38 | J21: =J19-J20 -> 22003 | K21: =IF(J21>0,(G21-J21)/J21," ") -> -0.59262919
A22: 707 | B22: Vente de marchandises dans la limite des 5% du CA | H22: =Temp!C90 -> 0 | J22: =Temp!D90 -> 0 | K22: =IF(J22>0,(G22-J22)/J22," ")
C24: MONTANT NET DU CHIFFRE D'AFFAIRES | H24: =pdt_act_annexe_N+H13+H22 -> 562308.95 | J24: =J19+J13+J22 -> 500655.03 | K24: =IF(J24>0,(H24-J24)/J24," ") -> 0.12314651
B26: Production stockée
A27: 7134 | C27: Activité de services | H27: =Temp!C23 -> 0 | J27: =Temp!D23 -> 0
A28: 72 | B28: Production immobilisée | H28: =Temp!C24 -> 0 | J28: =Temp!D24 -> 0 | K28: =IF(J28>0,(G28-J28)/J28," ")
A29: 74 | B29: Subventions d'exploitation | H29: =Temp!C25 -> 8433.84 | J29: =Temp!D25 -> 790.39 | K29: =IF(J29>0,(H29-J29)/J29," ") -> 9.6704791
A30: 747 | C30: Dont Quote-part des subventions d'investissement virées au résultat de l'exercice | G30: =Temp!C26 -> 0
A31: 757 | B31: Reventes d'immo | H31: =Temp!C30 -> 32500 | J31: =Temp!D30 -> 0 | K31: =IF(J31>0,(H31-J31)/J31," ")
A32: 781+791+7581 | B32: Reprises sur dépréciations, provisions (et amortissements), transferts de charges | H32: =Temp!C27+Temp!C32 -> 3569.57 | J32: =Temp!D27+Temp!D32 -> 0 | K32: =IF(J32>0,(H32-J32)/J32," ")
A33: 781 | C33: Reprises sur provisions | G33: =Temp!C28 -> 0 | J33: =Temp!D28 -> 0 | K33: =IF(J33>0,(G33-J33)/J33," ")
A34: 791+7581 | C34: Transfert de charges & remboursement d'assurances | G34: =Temp!C29+Temp!C32 -> 3569.57 | J34: =Temp!D29+Temp!D32 -> 0 | K34: =IF(J34>0,(G34-J34)/J34," ")
A35: 75 | B35: Autres produits | H35: =Temp!C31 -> 0.28 | J35: =Temp!D31 -> 0 | K35: =IF(J35>0,(H35-J35)/J35," ")
C36: TOTAL PRODUITS D'EXPLOITATION (I) | H36: =H35+repris_prov_N+subv_exploit_N+prod_immo_N+H27+CA_N+H31 -> 606812.64 | J36: =J35+J32+J29+J28+J27+J24+J31 -> 501445.42 | K36: =IF(J36>0,(H36-J36)/J36," ") -> 0.210127
A37: CHARGES D'EXPLOITATION | K37: =IF(J37>0,(G37-J37)/J37," ")
A39: 602 | B39: Achats de matières consommables et emballages | H39: =Temp!C33 -> 133398.96 | J39: =Temp!D33 -> 105187.06 | K39: =IF(J39>0,(H39-J39)/J39," ") -> 0.26820694
A40: 60211+60223 | C40: Lubrifiants, pièces détachées | G40: =Temp!C34 -> 60305.53 | J40: =Temp!D34 -> 40577.27 | K40: =IF(J40>0,(G40-J40)/J40," ") -> 0.48618993
A41: 60212 | C41: Carburants | G41: =Temp!C35 -> 65706.47 | J41: =Temp!D35 -> 60398.9 | K41: =IF(J41>0,(G41-J41)/J41," ") -> 0.087875276
A42: 60213 | C42: Matières incorporées au service | G42: =Temp!C36 -> 7386.96 | J42: =Temp!D36 -> 3706.92 | K42: =IF(J42>0,(G42-J42)/J42," ") -> 0.9927487
C43: Autres | G43: =H39-G40-G41-G42 -> -8.1854523e-12 | J43: =J39-J40-J41-J42 -> 503.97 | K43: =IF(J43>0,(G43-J43)/J43," ") -> -1
A44: 6032 | B44: Variations de stock | H44: =Temp!C37 -> 0 | J44: =Temp!D37 -> 2908.06 | K44: =IF(J44>0,(H44-J44)/J44," ") -> -1
A45: 607 | B45: Achats pour revente de marchandises | H45: =Temp!C89 -> 0 | J45: =Temp!D89 -> 0 | K45: =IF(J45>0,(H45-J45)/J45," ")
A46: 60x | B46: Autres achats | H46: =Temp!C38 -> 39600 | J46: =Temp!D38 -> 29241.84 | K46: =IF(J46>0,(H46-J46)/J46," ") -> 0.35422395
A47: 604 | C47: Sous-traitance | G47: =Temp!C39 -> 31710.4 | J47: =Temp!D39 -> 25043.22 | K47: =IF(J47>0,(G47-J47)/J47," ") -> 0.26622695
A48: 61+62 | B48: Charges externes | H48: =Temp!C40 -> 94569.91 | J48: =Temp!D40 -> 107236.58 | K48: =IF(J48>0,(H48-J48)/J48," ") -> -0.11811893
...
