Workbook

Sheet GuideGestion
B1: Nom de la Cuma | C1: CUMA DE TEST | G1: 999003
B2: Numéro de gestion | C2: TEST999001 | G2: 999356
B3: Commune | C3: PARIS
B4: Numéro d'agrément | C4: AGR999001 | G4: 999001
B5: Cloture N | G5: 75
B6: Cloture N-1 | C6: clot | G6: GDROOT
B7: Cloture N-2 | C7: clot | G7: Guide gestion
B8: Nom Comptable | C8: Ali BABA
B9: Tel Comptable | C9: 01.02.03.04.05
B10: mail comptable | C10: ali.baba@Cuma.fr
B11: nb_adh | C11: 64
A12: datedebut | C12: 01/01/2025 | D12: 01/01/2024 | E12: 01/01/2023 | F12: 01/01/2022
A13: datefin | C13: 31/12/2025 | D13: 31/12/2024 | E13: 31/12/2023 | F13: 31/12/2022
B14: DIFFERENTS NIVEAUX DE RESULTATS
A15: compte=(7-71) | B15: Chiffre d'affaires | C15: 562308.95 | D15: 500655.03 | E15: 517570.12 | F15: 418996.4
A16: compte=(70;74-746;748-749;60;61;62;63;64) | B16: Excédent brut d'exploitation | C16: 235445.07 | D16: 223675.74 | E16: 261796.64 | F16: 207917.37
A17: Compte=(6-66;68-686;688-689;7-76;78-786;788-79) | B17: Résultat courant | C17: 234249.79 | D17: -1379.57 | E17: 64422.42 | F17: 16236.84
A18: Compte=(695) | B18: Résultat IS | C18: 0 | D18: 0 | E18: 0 | F18: 0
A19: Compte=(67;687;69-694;696-699;77;787) | B19: Résultat exceptionnel | C19: 118480.12 | D19: 11409.29 | E19: 27443.23 | F19: -29391.43
B20: Résultat Net Comptable | C20: =C17+C19+C18 -> 352729.91 | D20: =D17+D19+D18 -> 10029.72 | E20: =E17+E19+E18 -> 91865.65 | F20: =F17+F19+F18 -> -13154.59
B21: ANALYSE DES CHARGES DE LA CUMA
A22: Compte=(70-7062;7064-708;709-71) | B22: Chiffre d'affaires corrigé | C22: 562308.95 | D22: 500655.03 | E22: 517570.12 | F22: 418996.4
A23: Compte=(70612010;70612020;70613010;70613020;70617010;70617020;70618010;70618020;70620010;70620020;70630010;70630020;70830010;70830020) | B23: CA Taux reduit | C23: 291429.01 | D23: 267485.71 | E23: 270858.68 | F23: 185654.28
A24: Compte=(6063;60211;603211;60223;60322;615;7581;7587;7912) credit=negatif | B24: Entretien réparation corrigé | C24: 93716.75 | D24: 80962.24 | E24: 68307.68 | F24: 63996.28
B25: Entretien réparation corrigé / CA corrigé | C25: =IF(C22=0,0,C24/C22*100) -> 16.666416 | D25: =IF(D22=0,0,D24/D22*100) -> 16.171263 | E25: =IF(E22=0,0,E24/E22*100) -> 13.197763 | F25: =IF(F22=0,0,F24/F22*100) -> 15.273706
A26: Compte=(6811;6816) credit=negatif | B26: Amortissement | C26: 0 | D26: 187408.12 | E26: 178752.87 | F26: 169664.89
B27: Amortissement / CA corrigé | C27: =IF(C22=0,0,C26/C22*100) -> 0 | D27: =IF(D22=0,0,D26/D22*100) -> 37.432585 | E27: =IF(E22=0,0,E26/E22*100) -> 34.536938 | F27: =IF(F22=0,0,F26/F22*100) -> 40.493162
A28: Compte=(64) credit=negatif | B28: Charges salariales | C28: 67728.85 | D28: 32405.75 | E28: 36312.8 | F28: 32604.53
B29: Charges salariales / CA corrigé | C29: =IF(C22=0,0,C28/C22*100) -> 12.044775 | D29: =IF(GuideGestion!D22=0,0,D28/GuideGestion!D22*100) -> 6.4726704 | E29: =IF(GuideGestion!E22=0,0,E28/GuideGestion!E22*100) -> 7.0160155 | F29: =IF(GuideGestion!F22=0,0,F28/GuideGestion!F22*100) -> 7.7815776
A30: Compte=(60212;603212) credit=negatif | B30: Carburant | C30: 65706.47 | D30: 60001.4 | E30: 78623.72 | F30: 66412.52
A31: Compte=(66) credit=negatif | B31: Frais financier | C31: 25126.49 | D31: 25599.09 | E31: 19672.66 | F31: 12972.81
B32: Frais financier / CA corrigé | C32: =IF(C22=0,0,C31/C22*100) -> 4.4684492 | D32: =IF(GuideGestion!D22=0,0,D31/GuideGestion!D22*100) -> 5.1131195 | E32: =IF(GuideGestion!E22=0,0,E31/GuideGestion!E22*100) -> 3.8009652 | F32: =IF(GuideGestion!F22=0,0,F31/GuideGestion!F22*100) -> 3.0961626
B33: FINANCEMENT DE L'EXERCICE
A34: Compte=(6-656;658-674;676-756;758-774;776-79) credit=positif | B34: Résultat (hors vente matériel) | C34: 201729.91 | D34: 122.12 | E34: 64426.84 | F34: 16236.84
A35: Compte=(68) credit=negatif | B35: Dotation Amort+prov | C35: 0 | D35: 187487.67 | E35: 178752.87 | F35: 171832.73
A36: Compte=(747;777;781;787) credit=positif | B36: Dotation rep/prov | C36: 0 | D36: 790.39 | E36: 11561.63 | F36: 0
B37: Dotation Amort+prov – rep/prov | C37: =C35-C36 -> 0 | D37: =D35-D36 -> 186697.28 | E37: =E35-E36 -> 167191.24 | F37: =F35-F36 -> 171832.73
A38: critere | C38: DB | D38: DB | E38: DB | F38: DB
A39: Compte=(8168) credit=negatif | B39: Emprunt remboursé par anticipation | C39: 0 | D39: 0 | E39: 0 | F39: 139125.55
A40: Compte=(164-16400;16402-16410;16412-16420;16422-16430;16432-16440;16442-16450;16452-16460;16462-16470;16472-16479;16482-16490;16492-16499;162) | B40: Remboursement du cap des emprunts long et moyen terme de l'année | C40: 311005.33 | D40: 223791.05 | E40: 305674.89 | F40: 326325.96
...

Sheet Publipostage
A1: nom_cuma | B1: num_gestion | C1: debut_periode | D1: fin_periode | E1: commune | F1: num_agrement | G1: comptable_nom | H1: comptable_tel | I1: comptable_mail | J1: nb_adherent | K1: ca | L1: ca_n1 | M1: ca_n2 | N1: ebe | O1: ebe_n1 | P1: ebe_n2 | Q1: rc | R1: rc_n1 | S1: rc_n2 | T1: rex | U1: rex_n1 | V1: rex_n2 | W1: rnc | X1: rnc_n1 | Y1: rnc_n2 | Z1: ca_corrige | AA1: ca_corrige_n1 | AB1: ca_corrige_n2 | AC1: entretien | AD1: entretien_n1 | AE1: entretien_n2 | AF1: entretien_ca | AG1: entretien_ca_n1 | AH1: entretien_ca_n2 | AI1: amort_ca | AJ1: amort_ca_n1 | AK1: amort_ca_n2 | AL1: tx_vetuste | AM1: tx_vetuste_n1 | AN1: tx_vetuste_n2 | AO1: chgsal | AP1: chgsal_n1 | AQ1: chgsal_n2 | AR1: chgsal_ca | AS1: chgsal_ca_n1 | AT1: chgsal_ca_n2 | AU1: carburant | AV1: carburant_n1 | AW1: carburant_n2 | AX1: ffinancier_ca | AY1: ffinancier_ca_n1 | AZ1: ffinancier_ca_n2 | BA1: res_hors_revente | BB1: dot_amort_reprise_prov | BC1: remb_emprunt | BD1: CAF | BE1: CAF_n1 | BF1: CAF_n2 | BG1: achat_immo | BH1: augment_PSCRCA | BI1: emprunt_LMT | BJ1: revente_immo | BK1: variation_KS | BL1: subvention | BM1: besoin_autofin | BN1: besoin_autofin_n1 | BO1: besoin_autofin_n2 | BP1: var_FdR | BQ1: var_FdR_n1 | BR1: var_FdR_n2 | BS1: fd_roulement | BT1: fd_roulement_n1 | BU1: fd_roulement_n2 | BV1: fd_roulement_ca | BW1: fd_roulement_ca_n1 | BX1: fd_roulement_ca_n2 | BY1: actif_circulant | BZ1: actif_circulant_n1 | CA1: actif_circulant_n2 | CB1: besoin_fdr | CC1: besoin_fdr_n1 | CD1: besoin_fdr_n2 | CE1: creance_ca | CF1: creance_ca_n1 | CG1: creance_ca_n2 | CH1: treso_net | CI1: treso_net_n1 | CJ1: treso_net_n2 | CK1: CS_CA | CL1: CS_CA_n1 | CM1: CS_CA_n2 | CN1: CS_val_brute_mat | CO1: CS_val_brute_mat_n1 | CP1: CS_val_brute_mat_n2 | CQ1: CS_k_propres | CR1: CS_k_propres_n1 | CS1: CS_k_propres_n2 | CT1: tx_endette | CU1: tx_endette_n1 | CV1: tx_endette_n2 | CW1: k_propres_passif | CX1: k_propres_passif_n1 | CY1: k_propres_passif_n2 | CZ1: subvention | DA1: variation_cap | DB1: vetuste | DC1: vetuste_n1 | DD1: vetuste_n2 | DE1: Num_gest | DF1: Capitaux_Permanent | DG1: Capitaux_Permanent_n1 | DH1: Capitaux_Permanent_n2 | DI1: Creance_1an | DJ1: Creance_1an_n1 | DK1: Creance_1an_n2 | DL1: Emprunt_recevoir | DM1: Emprunt_recevoir_n1 | DN1: Emprunt_recevoir_n2 | DO1: Emprunt_anticipation | DP1: Emprunt_anticipation_n1 | DQ1: Emprunt_anticipation_n2 | DR1: provision_creance_n | DS1: provision_creance_n1 | DT1: entretien_valBruteMateriel_n | DU1: entretien_valBruteMateriel_n1 | DV1: entretien_valBruteMateriel_n2 | DW1: valBruteMateriel_amort_n | DX1: valBruteMateriel_amort_n1 | DY1: valBruteMateriel_amort_n2 | DZ1: CAF_CA_n | EA1: CAF_CA_n1 | EB1: CAF_CA_n2 | EC1: Creance_CA_TTC_n | ED1: Creance_CA_TTC_n1 | EE1: Creance_CA_TTC_n2 | EF1: Investissement_moy_N_n1_n2 | EG1: Investissement_moy_N_n1_n2_Sur_N3 | EH1: Immo_n | EI1: Immo_n1 | EJ1: Immo_n2 | EK1: ResultatIS_n | EL1: ResultatIS_n1 | EM1: ResultatIS_n2 | EN1: plu_moins_value_n | EO1: plu_moins_value_n1 | EP1: plu_moins_value_n2 | EQ1: res_courant_plu_val_n | ER1: res_courant_plu_val_n1 | ES1: res_courant_plu_val_n2
A2: =GuideGestion!C1 -> CUMA DE TEST | B2: =GuideGestion!C2 -> TEST999001 | C2: =GuideGestion!C12 -> 01/01/2025 | D2: =GuideGestion!C13 -> 31/12/2025 | E2: =GuideGestion!C3 -> PARIS | F2: =GuideGestion!C4 -> AGR999001 | G2: =GuideGestion!C8 -> Ali BABA | H2: =GuideGestion!C9 -> 01.02.03.04.05 | I2: =GuideGestion!C10 -> ali.baba@Cuma.fr | J2: =GuideGestion!C11 -> 64 | K2: =GuideGestion!C15 -> 562308.95 | L2: =GuideGestion!D15 -> 500655.03 | M2: =GuideGestion!E15 -> 517570.12 | N2: =GuideGestion!C16 -> 235445.07 | O2: =GuideGestion!D16 -> 223675.74 | P2: =GuideGestion!E16 -> 261796.64 | Q2: =GuideGestion!C17 -> 234249.79 | R2: =GuideGestion!D17 -> -1379.57 | S2: =GuideGestion!E17 -> 64422.42 | T2: =GuideGestion!C19 -> 118480.12 | U2: =GuideGestion!D19 -> 11409.29 | V2: =GuideGestion!E19 -> 27443.23 | W2: =GuideGestion!C20 -> 352729.91 | X2: =GuideGestion!D20 -> 10029.72 | Y2: =GuideGestion!E20 -> 91865.65 | Z2: =GuideGestion!C22 -> 562308.95 | AA2: =GuideGestion!D22 -> 500655.03 | AB2: =GuideGestion!E22 -> 517570.12 | AC2: =GuideGestion!C24 -> 93716.75 | AD2: =GuideGestion!D24 -> 80962.24 | AE2: =GuideGestion!E24 -> 68307.68 | AF2: =GuideGestion!C25 -> 16.666416 | AG2: =GuideGestion!D25 -> 16.171263 | AH2: =GuideGestion!E25 -> 13.197763 | AI2: =GuideGestion!C27 -> 0 | AJ2: =GuideGestion!D27 -> 37.432585 | AK2: =GuideGestion!E27 -> 34.536938 | AL2: =GuideGestion!C65 -> 30.345722 | AM2: =GuideGestion!D65 -> 37.368341 | AN2: =GuideGestion!E65 -> 32.140424 | AO2: =GuideGestion!C28 -> 67728.85 | AP2: =GuideGestion!D28 -> 32405.75 | AQ2: =GuideGestion!E28 -> 36312.8 | AR2: =GuideGestion!C29 -> 12.044775 | AS2: =GuideGestion!D29 -> 6.4726704 | AT2: =GuideGestion!E29 -> 7.0160155 | AU2: =GuideGestion!C30 -> 65706.47 | AV2: =GuideGestion!D30 -> 60001.4 | AW2: =GuideGestion!E30 -> 78623.72 | AX2: =GuideGestion!C32 -> 4.4684492 | AY2: =GuideGestion!D32 -> 5.1131195 | AZ2: =GuideGestion!E32 -> 3.8009652 | BA2: =GuideGestion!C34 -> 201729.91 | BB2: =GuideGestion!C37 -> 0 | BC2: =GuideGestion!C41 -> 311005.33 | BD2: =GuideGestion!C44 -> -109275.42 | BE2: =GuideGestion!D44 -> -36971.65 | BF2: =GuideGestion!E44 -> -74056.81 | BG2: =GuideGestion!C42 -> 600907.92 | BH2: =GuideGestion!C47 -> 68.85 | BI2: =GuideGestion!C52 -> 566600 | BJ2: =GuideGestion!C48 -> 151000 | BK2: =GuideGestion!C50 -> 0 | BL2: =GuideGestion!C53 -> 0 | BM2: =GuideGestion!C55 -> -116623.23 | BN2: =GuideGestion!D55 -> 336.79 | BO2: =GuideGestion!E55 -> -555878.85 | BP2: =GuideGestion!C60 -> 7347.81 | BQ2: =GuideGestion!D60 -> -37387.99 | BR2: =GuideGestion!E60 -> 493383.67 | BS2: =GuideGestion!C74 -> 295385.8 | BT2: =GuideGestion!D74 -> 288037.99 | BU2: =GuideGestion!E74 -> 325425.98 | BV2: =GuideGestion!C75 -> 52.530873 | BW2: =GuideGestion!D75 -> 57.532227 | BX2: =GuideGestion!E75 -> 62.875728 | BY2: =GuideGestion!C76+GuideGestion!C78 -> 403551.6 | BZ2: =GuideGestion!D76+GuideGestion!D78 -> 329063.79 | CA2: =GuideGestion!E76+GuideGestion!E78 -> 396993.68 | CB2: =BY2-GuideGestion!C99-GuideGestion!C101+GuideGestion!C106 -> 367818.69 | CC2: =BZ2-GuideGestion!D99-GuideGestion!D101+GuideGestion!D106 -> 232999.21 | CD2: =CA2-GuideGestion!E99-GuideGestion!E101+GuideGestion!E106 -> 363523.11 | CE2: =GuideGestion!C80 -> 18.452699 | CF2: =GuideGestion!D80 -> 24.116849 | CG2: =GuideGestion!E80 -> 28.158283 | CH2: =BS2-CB2 -> -72432.89 | CI2: =BT2-CC2 -> 55038.78 | CJ2: =BU2-CD2 -> -38097.13 | CK2: =GuideGestion!C85 -> 26.829023 | CL2: =GuideGestion!D85 -> 30.132924 | CM2: =GuideGestion!E85 -> 27.159991 | CN2: =GuideGestion!C88 -> 4.9336205 | CO2: =GuideGestion!D88 -> 6.0753609 | CP2: =GuideGestion!E88 -> 5.9600367 | CQ2: =GuideGestion!C91 -> 13.943639 | CR2: =GuideGestion!D91 -> 20.688374 | CS2: =GuideGestion!E91 -> 20.046114 | CT2: =GuideGestion!C107 -> 53.428895 | CU2: =GuideGestion!D107 -> 57.124159 | CV2: =GuideGestion!E107 -> 61.14275 | CW2: =GuideGestion!C105 -> 41.735645 | CX2: =GuideGestion!D105 -> 36.880368 | CY2: =GuideGestion!E105 -> 34.553129 | CZ2: =GuideGestion!C53 -> 0 | DA2: =GuideGestion!C50 -> 0 | DB2: =GuideGestion!C65 -> 30.345722 | DC2: =GuideGestion!D65 -> 37.368341 | DD2: =GuideGestion!E65 -> 32.140424 | DE2: =GuideGestion!C2 -> TEST999001 | DF2: =IF((GuideGestion!C90+GuideGestion!C106+GuideGestion!C72)<>0,GuideGestion!C90/(GuideGestion!C90+GuideGestion!C106+GuideGestion!C72),0) -> 0.42318965 | DG2: =IF((GuideGestion!D90+GuideGestion!D106+GuideGestion!D72)<>0,GuideGestion!D90/(GuideGestion!D90+GuideGestion!D106+GuideGestion!D72),0) -> 0.38763715 | DH2: =IF((GuideGestion!E106+GuideGestion!E90+GuideGestion!E72)<>0,GuideGestion!E90/(GuideGestion!E106+GuideGestion!E90+GuideGestion!E72),0) -> 0.35132546 | DI2: =GuideGestion!C45 -> 0 | DJ2: =GuideGestion!D45 -> 25500.34 | DK2: =GuideGestion!E45 -> 10108.65 | DL2: =GuideGestion!C54 -> 0 | DM2: =GuideGestion!D54 -> 0 | DN2: =GuideGestion!E54 -> 0 | DO2: =GuideGestion!C39 -> 0 | DP2: =GuideGestion!D39 -> 0 | DQ2: =GuideGestion!E39 -> 0 | DR2: =GuideGestion!C59 -> 0 | DS2: =GuideGestion!D59 -> -79.55 | DT2: =GuideGestion!C92 -> 3.0648068 | DU2: =GuideGestion!D92 -> 3.2604289 | DV2: =GuideGestion!E92 -> 2.8961406 | DW2: =GuideGestion!C93 -> 0 | DX2: =GuideGestion!D93 -> 1325.0107 | DY2: =GuideGestion!E93 -> 1319.4619 | DZ2: =GuideGestion!C94 -> -19.433342 | EA2: =GuideGestion!D94 -> -7.3846557 | EB2: =GuideGestion!E94 -> -14.308556 | EC2: =GuideGestion!C95 -> 16.404579 | ED2: =GuideGestion!D95 -> 21.033857 | EE2: =GuideGestion!E95 -> 24.535233 | EF2: =IF(SUM(GuideGestion!C43:E43)>0,AVERAGE(GuideGestion!C43:E43),0) -> 368385.97 | EG2: =IF(GuideGestion!F87<>0,Publipostage!EF2/GuideGestion!F87,0)*100 -> 15.870409 | EH2: =GuideGestion!C43 -> 574657.92 | EI2: =GuideGestion!D43 -> 143350 | EJ2: =GuideGestion!E43 -> 387150 | EK2: =GuideGestion!C18 -> 0 | EL2: =GuideGestion!D18 -> 0 | EM2: =GuideGestion!E18 -> 0 | EN2: =GuideGestion!C49 -> 32500 | EO2: =GuideGestion!D49 -> 0 | EP2: =GuideGestion!E49 -> 0 | EQ2: =Q2-EN2 -> 201749.79 | ER2: =R2-EO2 -> -1379.57 | ES2: =S2-EP2 -> 64422.42
